<?xml version="1.0"?>
<robot xmlns:xacro="http://www.ros.org/wiki/xacro">

  <xacro:include filename="$(find manipulator_description)/urdf/transmission.xacro" />
  <!-- <xacro:include filename="$(find manipulator_description)/urdf/robotis_manipulator_h.gazebo" /> -->
  <xacro:include filename="$(find manipulator_description)/urdf/materials.xacro" />

  <xacro:property name="pi" value="3.141592654" />
  <xacro:property name="prefix_val" value="" />

  <xacro:macro name="manipulator_h_arm" params="prefix joint_limited parent *origin">

    <!-- Suffix prefix with underscore -->
    <xacro:if value="${prefix.__len__()}">
      <xacro:property name="prefix_val" value="${prefix + '_'}" />
    </xacro:if>

    <!-- First element of the arm fixed to the parent -->
    <joint name="${parent}_${prefix_val}_base_joint" type="fixed">
      <xacro:insert_block name="origin" />
      <parent link="${parent}" />
      <child link="${prefix_val}shoulder_link" />
    </joint>

    <!-- link 1 -->
    <link name="${prefix_val}shoulder_link">
      <collision>
        <origin xyz="0 0 0.063" rpy="0 0 ${pi}"/>
        <geometry>
      <box size="0.06 0.06 0.126"/>
        </geometry>
      </collision>
      <visual>
        <origin xyz="0 0 0" rpy="0 0 ${pi}"/>
        <geometry>
          <mesh filename="package://manipulator_description/meshes/link_1.stl" scale="0.001 0.001 0.001"/>
        </geometry>
        <material name="grey"/>
      </visual>

      <inertial>
        <origin xyz="0 0 0" rpy="0 0 0"/>
        <mass value="0.936"/>
        <inertia
        ixx="1.0" ixy="0.0" ixz="0.0"
        iyy="1.0" iyz="0.0"
        izz="1.0"/>
      </inertial>
    </link>

    <!-- Joint 1 -->
    <joint name="${prefix_val}shoulder_pan_joint" type="revolute">
      <parent link="${prefix_val}shoulder_link" />
      <child link = "${prefix_val}upper_arm_link" />
      <origin xyz="0 0 0.126" rpy="0 0 0"/>
      <axis xyz="0 0 1"/>
      <limit velocity="6.5" effort="1000" lower="${-pi*0.95}" upper="${pi*0.95}" />
      <dynamics damping="0.7"/>
    </joint>

    <!-- link 2 -->
    <link name="${prefix_val}upper_arm_link">
      <collision>
        <origin xyz="0 0 0.033" rpy="0 0 ${pi}"/>
        <geometry>
      <box size="0.07 0.15 0.08"/>
        </geometry>
      </collision>

      <visual>
        <origin xyz="0 0 -0.126" rpy="0 0 ${pi}"/>
        <geometry>
          <mesh filename="package://manipulator_description/meshes/link_2.stl" scale="0.001 0.001 0.001"/>
        </geometry>
        <material name="grey"/>
      </visual>

      <inertial>
        <origin xyz="0 0 0" rpy="0 0 0"/>
        <mass value="1.030"/>
        <inertia
        ixx="1.0" ixy="0.0" ixz="0.0"
        iyy="1.0" iyz="0.0"
        izz="1.0"/>
      </inertial>
    </link>

    <!-- Joint 2 -->
    <joint name="${prefix_val}shoulder_lift_joint" type="revolute">
      <parent link="${prefix_val}upper_arm_link" />
      <child link = "${prefix_val}forearm_link" />
      <origin xyz="0 0 0.033" rpy="0 0 0"/>
      <axis xyz="0 1 0"/>
      <limit velocity="6.5" effort="1000" lower="${-pi*0.6}" upper="${pi*0.6}" />
      <dynamics damping="0.7"/>
    </joint>

    <!-- link 3 -->
    <link name="${prefix_val}forearm_link">
      <collision>
        <origin xyz="0.02 0 0.15" rpy="0 0 ${pi}"/>
        <geometry>
      <box size="0.1 0.15 0.25"/>
        </geometry>
      </collision>

      <visual>
        <origin xyz="0 0 -0.159" rpy="0 0 ${pi}"/>
        <geometry>
          <mesh filename="package://manipulator_description/meshes/link_3.stl" scale="0.001 0.001 0.001"/>
        </geometry>
        <material name="grey"/>
      </visual>

      <inertial>
        <origin xyz="0 0 0" rpy="0 0 0"/>
        <mass value="1.404"/>
        <inertia
        ixx="1.0" ixy="0.0" ixz="0.0"
        iyy="1.0" iyz="0.0"
        izz="1.0"/>
      </inertial>
    </link>

    <!-- Joint 3 -->
    <joint name="${prefix_val}elbow_joint" type="revolute">
      <parent link="${prefix_val}forearm_link" />
      <child link = "${prefix_val}wrist_1_link" />
      <origin xyz="0.03 0.0 0.264" rpy="0 ${45.0*pi/180.0} 0" />
      <axis xyz="0 1 0"/>
      <limit velocity="6.5" effort="1000" lower="${-pi*0.4}" upper="${pi*0.72}" />
      <dynamics damping="0.7"/>
    </joint>

    <!-- link 4 -->
    <link name="${prefix_val}wrist_1_link">
      <collision>
        <origin xyz="-0.01 0.0 0.1" rpy="0 0 ${pi}" />
        <geometry>
      <box size="0.1 0.15 0.25" />
        </geometry>
      </collision>

      <visual>
        <origin xyz="-0.03 0 -0.423" rpy="0 0 ${pi}" />
        <geometry>
          <mesh filename="package://manipulator_description/meshes/link_4.stl" scale="0.001 0.001 0.001"/>
        </geometry>
        <material name="grey"/>
      </visual>

      <inertial>
        <origin xyz="0 0 0" rpy="0 0 0" />
        <mass value="1.236" />
        <inertia
        ixx="1.0" ixy="0.0" ixz="0.0"
        iyy="1.0" iyz="0.0"
        izz="1.0"/>
      </inertial>
    </link>

    <!-- Joint 4 -->
    <joint name="${prefix_val}wrist_1_joint" type="revolute">
      <parent link="${prefix_val}wrist_1_link" />
      <child link = "${prefix_val}wrist_2_link" />
      <origin xyz="-0.03 0.0 0.231" rpy="0 0 0" />
      <axis xyz="0 0 1" />
      <limit velocity="6.5" effort="1000" lower="${-pi}" upper="${pi}" />
      <dynamics damping="0.7"/>
    </joint>

    <!-- link 5 -->
    <link name="${prefix_val}wrist_2_link">
      <collision>
        <origin xyz="0.0 0.0 0.03" rpy="0 0 ${pi}" />
        <geometry>
      <box size="0.06 0.13 0.09" />
        </geometry>
      </collision>

      <visual>
        <origin xyz="0 0 -0.654" rpy="0 0 ${pi}" />
        <geometry>
          <mesh filename="package://manipulator_description/meshes/link_5.stl" scale="0.001 0.001 0.001"/>
        </geometry>
        <material name="grey"/>
      </visual>

      <inertial>
        <origin xyz="0 0 0" rpy="0 0 0" />
        <mass value="0.491" />
        <inertia
        ixx="1.0" ixy="0.0" ixz="0.0"
        iyy="1.0" iyz="0.0"
        izz="1.0"/>
      </inertial>
    </link>

    <!-- Joint 5 -->
    <joint name="${prefix_val}wrist_2_joint" type="revolute">
      <parent link="${prefix_val}wrist_2_link" />
      <child link = "${prefix_val}wrist_3_link" />
      <origin xyz="0.0 0.0 0.027" rpy="0 0 0" />
      <axis xyz="0 1 0" />
      <limit velocity="6.5" effort="1000" lower="${-pi*0.5}" upper="${pi*0.5}" />
      <dynamics damping="0.7"/>
    </joint>

    <!-- link 6 -->
    <link name="${prefix_val}wrist_3_link">
      <collision>
        <origin xyz="0.0 0.0 0.08" rpy="0 0 ${pi}" />
        <geometry>
      <box size="0.07 0.07 0.08" />
        </geometry>
      </collision>

      <visual>
        <origin xyz="0 0 -0.681" rpy="0 0 ${pi}" />
        <geometry>
          <mesh filename="package://manipulator_description/meshes/link_6.stl" scale="0.001 0.001 0.001"/>
        </geometry>
        <material name="grey"/>
      </visual>

      <inertial>
        <origin xyz="0 0 0" rpy="0 0 0" />
        <mass value="0.454" />
        <inertia
        ixx="1.0" ixy="0.0" ixz="0.0"
        iyy="1.0" iyz="0.0"
        izz="1.0"/>
      </inertial>
    </link>

    <!-- Joint 6 -->
    <joint name="${prefix_val}wrist_3_joint" type="revolute">
      <parent link="${prefix_val}wrist_3_link" />
      <child link = "${prefix_val}ee_link" />
      <origin xyz="0.0 0.0 0.123" rpy="0 0 0" />
      <axis xyz="0 0 1" />
      <limit velocity="6.5" effort="1000" lower="${-pi}" upper="${pi}" />
      <dynamics damping="0.7"/>
    </joint>

    <!-- End Effector -->
    <link name="${prefix_val}ee_link">
      <collision>
        <origin xyz="0.0 0.0 0.0" rpy="0 0 0" />
        <geometry>
          <box size = "0.01 0.01 0.01"/>
        </geometry>
      </collision>

      <visual>
        <origin xyz="0.0 0.0 0.0" rpy="0 0 0" />
        <geometry>
          <box size = "0.01 0.01 0.01"/>
        </geometry>
        <material name="red"/>
      </visual>

      <inertial>
        <origin xyz="0.0 0.0 0.0" rpy="0 0 0" />
        <mass value="0.001" />
        <inertia
        ixx="1.0" ixy="0.0" ixz="0.0"
        iyy="1.0" iyz="0.0"
        izz="1.0"/>
      </inertial>
    </link>

    <xacro:manipulator_arm_transmission prefix="${prefix_val}" />
  </xacro:macro>
</robot>
